2019-01-30 01:42:57,713 - telegram.ext.dispatcher - ERROR - An uncaught error was raised while processing the update
Traceback (most recent call last):
  File "D:\PROGRAM\lib\site-packages\telegram\ext\dispatcher.py", line 279, in process_update
    handler.handle_update(update, self)
  File "D:\PROGRAM\lib\site-packages\telegram\ext\callbackqueryhandler.py", line 143, in handle_update
    return self.callback(dispatcher.bot, update, **optional_args)
TypeError: button() missing 1 required positional argument: 'Card'
2019-01-30 01:45:39,097 - telegram.ext.dispatcher - ERROR - An uncaught error was raised while processing the update
Traceback (most recent call last):
  File "D:\PROGRAM\lib\site-packages\telegram\ext\dispatcher.py", line 279, in process_update
    handler.handle_update(update, self)
  File "D:\PROGRAM\lib\site-packages\telegram\ext\callbackqueryhandler.py", line 143, in handle_update
    return self.callback(dispatcher.bot, update, **optional_args)
TypeError: button() missing 1 required positional argument: 'Card'
2019-01-30 01:49:02,561 - telegram.ext.dispatcher - ERROR - An uncaught error was raised while processing the update
Traceback (most recent call last):
  File "D:\PROGRAM\lib\site-packages\telegram\ext\dispatcher.py", line 279, in process_update
    handler.handle_update(update, self)
  File "D:\PROGRAM\lib\site-packages\telegram\ext\callbackqueryhandler.py", line 143, in handle_update
    return self.callback(dispatcher.bot, update, **optional_args)
TypeError: button() missing 1 required positional argument: 'Card'
2019-01-30 01:58:34,284 - telegram.ext.dispatcher - ERROR - An uncaught error was raised while processing the update
Traceback (most recent call last):
  File "D:\PROGRAM\lib\site-packages\telegram\ext\dispatcher.py", line 279, in process_update
    handler.handle_update(update, self)
  File "D:\PROGRAM\lib\site-packages\telegram\ext\callbackqueryhandler.py", line 143, in handle_update
    return self.callback(dispatcher.bot, update, **optional_args)
TypeError: button() missing 1 required positional argument: 'card'
2019-01-31 08:15:03,050 - telegram.ext.updater - ERROR - Error while getting Updates: Conflict: terminated by other getUpdates request; make sure that only one bot instance is running (409)
2019-01-31 08:15:03,200 - __main__ - WARNING - Update "None" caused error "Conflict: terminated by other getUpdates request; make sure that only one bot instance is running (409)"
2019-01-31 08:15:08,578 - telegram.ext.updater - ERROR - Error while getting Updates: Conflict: terminated by other getUpdates request; make sure that only one bot instance is running (409)
2019-01-31 08:15:08,580 - __main__ - WARNING - Update "None" caused error "Conflict: terminated by other getUpdates request; make sure that only one bot instance is running (409)"
2019-01-31 08:15:14,943 - telegram.ext.updater - ERROR - Error while getting Updates: Conflict: terminated by other getUpdates request; make sure that only one bot instance is running (409)
2019-01-31 08:15:14,944 - __main__ - WARNING - Update "None" caused error "Conflict: terminated by other getUpdates request; make sure that only one bot instance is running (409)"
2019-01-31 08:15:21,544 - telegram.ext.updater - ERROR - Error while getting Updates: Conflict: terminated by other getUpdates request; make sure that only one bot instance is running (409)
2019-01-31 08:15:21,545 - __main__ - WARNING - Update "None" caused error "Conflict: terminated by other getUpdates request; make sure that only one bot instance is running (409)"
2019-01-31 08:15:29,876 - telegram.ext.updater - ERROR - Error while getting Updates: Conflict: terminated by other getUpdates request; make sure that only one bot instance is running (409)
2019-01-31 08:15:29,876 - __main__ - WARNING - Update "None" caused error "Conflict: terminated by other getUpdates request; make sure that only one bot instance is running (409)"
2019-01-31 08:15:39,399 - telegram.ext.updater - ERROR - Error while getting Updates: Conflict: terminated by other getUpdates request; make sure that only one bot instance is running (409)
2019-01-31 08:15:39,400 - __main__ - WARNING - Update "None" caused error "Conflict: terminated by other getUpdates request; make sure that only one bot instance is running (409)"
2019-01-31 08:15:51,380 - telegram.ext.updater - ERROR - Error while getting Updates: Conflict: terminated by other getUpdates request; make sure that only one bot instance is running (409)
2019-01-31 08:15:51,380 - __main__ - WARNING - Update "None" caused error "Conflict: terminated by other getUpdates request; make sure that only one bot instance is running (409)"
2019-01-31 08:16:07,143 - telegram.ext.updater - ERROR - Error while getting Updates: Conflict: terminated by other getUpdates request; make sure that only one bot instance is running (409)
2019-01-31 08:16:07,143 - __main__ - WARNING - Update "None" caused error "Conflict: terminated by other getUpdates request; make sure that only one bot instance is running (409)"
2019-01-31 08:16:28,653 - telegram.ext.updater - ERROR - Error while getting Updates: Conflict: terminated by other getUpdates request; make sure that only one bot instance is running (409)
2019-01-31 08:16:28,654 - __main__ - WARNING - Update "None" caused error "Conflict: terminated by other getUpdates request; make sure that only one bot instance is running (409)"
2019-01-31 08:16:58,736 - telegram.ext.updater - ERROR - Error while getting Updates: Conflict: terminated by other getUpdates request; make sure that only one bot instance is running (409)
2019-01-31 08:16:58,737 - __main__ - WARNING - Update "None" caused error "Conflict: terminated by other getUpdates request; make sure that only one bot instance is running (409)"
2019-01-31 08:17:41,564 - telegram.ext.updater - ERROR - Error while getting Updates: Conflict: terminated by other getUpdates request; make sure that only one bot instance is running (409)
2019-01-31 08:17:41,565 - __main__ - WARNING - Update "None" caused error "Conflict: terminated by other getUpdates request; make sure that only one bot instance is running (409)"
2019-01-31 08:18:15,968 - telegram.ext.updater - ERROR - Error while getting Updates: Conflict: terminated by other getUpdates request; make sure that only one bot instance is running (409)
2019-01-31 08:18:15,968 - __main__ - WARNING - Update "None" caused error "Conflict: terminated by other getUpdates request; make sure that only one bot instance is running (409)"
